Workbook

Sheet Detail1
A1: Details for Sum of Ticket Total Tons
A3: Territory | B3: Project Name | C3: Project Number | D3: Work Phase | E3: Type Of Building | F3: Udf_ProjectSquareFootage | G3: Vendor | H3: Vendor Contact | I3: Facility | J3: Facility Address | K3: Container Number | L3: Haul Date | M3: Month + Year | N3: Ticket Number | O3: Ticket Image | P3: Type | Q3: Ticket Total Tons | R3: GM Diversion % | S3: GM Reused % | T3: GM Recycled % | U3: GM Disposed % | V3: GM Reused Tons | W3: GM Recycled Tons | X3: GM Disposed Tons | Y3: GM Total Tons | Z3: Alternate Daily Cover (ADC) | AA3: Asphalt - Pavement & Grinding | AB3: Cardboard & Paper Products | AC3: Concrete | AD3: Deconstructed & Reuse Items | AE3: Drywall - Demo & painted | AF3: Metal | AG3: Mixed Recyclables | AH3: Plastics & Plastic Packaging Materials | AI3: Waste (Trash) | AJ3: Appliances & Equipment | AK3: Aritificial Grass/Synthetic Turf | AL3: Asphalt - Roofing | AM3: Bricks, Masonry & Stone Products | AN3: Carpet & Padding | AO3: Ceiling Tiles | AP3: Compost | AQ3: Compostable Food Waste | AR3: Donated Food | AS3: Drywall - Clean/Unpainted | AT3: EPS Styrofoam | AU3: eWaste | AV3: Glass Bottles & Containers | AW3: Glass Plate or Tempered | AX3: High-Density Polyethylene (HDPE) | AY3: Miscellaneous Debris | AZ3: Mixed Food Waste | BA3: Paint | BB3: Paint - oil based | BC3: Porcelain | BD3: Trash Sorted for Recovery | BE3: Wood - Clean | BF3: Wood - Painted/Stained Recoverable | BG3: Wood - Pallets | BH3: EW Diversion % | BI3: EW Reused % | BJ3: EW Recycled % | BK3: EW Disposed % | BL3: EW Reused Tons | BM3: EW Recycled Tons | BN3: EW Disposed Tons | BO3: EW Total Tons | BP3: Dirt/Soil-Clean Fill* | BQ3: Green Waste* | BR3: Rock, Sand, Gravel & other inerts* | BS3: Haz Diversion % | BT3: Haz Reused % | BU3: Haz Recycled % | BV3: Haz Disposed % | BW3: Haz Reused Tons | BX3: Haz Recycled Tons | BY3: Haz Disposed Tons | BZ3: Haz Total Tons | CA3: Batteries* | CB3: Dirt/Soil-Contaminated Non-Hazardous* | CC3: Dirt/Soil-Contaminated, Hazardous* | CD3: Dirt/Soil-Hazardous* | CE3: Fluorescent Bulbs* | CF3: Materials Containing Asbestos* | CG3: Materials with Lead-Based Paint* | CH3: Other Hazardous Waste & Materials* | CI3: PCBs - Polychlorinated Biphenyls* | CJ3: Thermostats & Mercury - Containing Equipment* | CK3: Universal Waste - Other* | CL3: Wood - Treated/Hazardous* | CM3: Hauler Comment | CN3: Submitted By | CO3: Submitted Title | CP3: Submitted Date | CQ3: Verified by | CR3: Verified Date | CS3: Review Comment
A4: Oakland/San Francisco/San Jose | B4: UCB Gateway | C4: 210784 | E4: Higher Education | Laboratory / Research | 005 | 004 | F4: 368 | G4: Silverado Contractors | H4: Samantha Chen | I4: Argent Materials, Inc | J4: 8300 Baldwin St, Oakland, CA 94621 | L4: 11/11/2022 | M4: 44866 | N4: 7140424 | O4: Click Here To View | P4: Demolition | Q4: 13.53 | R4: 100.00% | S4: 0.00% | T4: 100.00% | U4: 0.00% | W4: 13.53 | Y4: 13.53 | AC4: 13.53 | BH4: 0.00% | BI4: 0.00% | BJ4: 0.00% | BK4: 0.00% | BS4: 0.00% | BT4: 0.00% | BU4: 0.00% | BV4: 0.00% | CN4: Katherine Ibarra | CP4: 08/01/2023 | CQ4: Katherine Ibarra
A5: Oakland/San Francisco/San Jose | B5: UCB Gateway | C5: 210784 | E5: Higher Education | Laboratory / Research | 005 | 004 | F5: 368 | G5: Silverado Contractors | H5: Samantha Chen | I5: Argent Materials, Inc | J5: 8300 Baldwin St, Oakland, CA 94621 | L5: 11/04/2022 | M5: 44866 | N5: 7140492 | O5: Click Here To View | P5: Demolition | Q5: 13.98 | R5: 100.00% | S5: 0.00% | T5: 100.00% | U5: 0.00% | W5: 13.98 | Y5: 13.98 | AC5: 13.98 | BH5: 0.00% | BI5: 0.00% | BJ5: 0.00% | BK5: 0.00% | BS5: 0.00% | BT5: 0.00% | BU5: 0.00% | BV5: 0.00% | CN5: Katherine Ibarra | CP5: 08/01/2023 | CQ5: Katherine Ibarra
A6: Oakland/San Francisco/San Jose | B6: UCB Gateway | C6: 210784 | E6: Higher Education | Laboratory / Research | 005 | 004 | F6: 368 | G6: Silverado Contractors | H6: Samantha Chen | I6: Argent Materials, Inc | J6: 8300 Baldwin St, Oakland, CA 94621 | L6: 11/04/2022 | M6: 44866 | N6: 7140546 | O6: Click Here To View | P6: Demolition | Q6: 14.01 | R6: 100.00% | S6: 0.00% | T6: 100.00% | U6: 0.00% | W6: 14.01 | Y6: 14.01 | AC6: 14.01 | BH6: 0.00% | BI6: 0.00% | BJ6: 0.00% | BK6: 0.00% | BS6: 0.00% | BT6: 0.00% | BU6: 0.00% | BV6: 0.00% | CN6: Katherine Ibarra | CP6: 08/01/2023 | CQ6: Katherine Ibarra
A7: Oakland/San Francisco/San Jose | B7: UCB Gateway | C7: 210784 | E7: Higher Education | Laboratory / Research | 005 | 004 | F7: 368 | G7: Silverado Contractors | H7: Samantha Chen | I7: Argent Materials, Inc | J7: 8300 Baldwin St, Oakland, CA 94621 | L7: 11/07/2022 | M7: 44866 | N7: 7140757 | O7: Click Here To View | P7: Demolition | Q7: 13.76 | R7: 100.00% | S7: 0.00% | T7: 100.00% | U7: 0.00% | W7: 13.76 | Y7: 13.76 | AC7: 13.76 | BH7: 0.00% | BI7: 0.00% | BJ7: 0.00% | BK7: 0.00% | BS7: 0.00% | BT7: 0.00% | BU7: 0.00% | BV7: 0.00% | CN7: Katherine Ibarra | CP7: 08/01/2023 | CQ7: Katherine Ibarra
A8: Oakland/San Francisco/San Jose | B8: UCB Gateway | C8: 210784 | E8: Higher Education | Laboratory / Research | 005 | 004 | F8: 368 | G8: Silverado Contractors | H8: Samantha Chen | I8: Argent Materials, Inc | J8: 8300 Baldwin St, Oakland, CA 94621 | L8: 11/07/2022 | M8: 44866 | N8: 7140808 | O8: Click Here To View | P8: Demolition | Q8: 17.42 | R8: 100.00% | S8: 0.00% | T8: 100.00% | U8: 0.00% | W8: 17.42 | Y8: 17.42 | AC8: 17.42 | BH8: 0.00% | BI8: 0.00% | BJ8: 0.00% | BK8: 0.00% | BS8: 0.00% | BT8: 0.00% | BU8: 0.00% | BV8: 0.00% | CN8: Katherine Ibarra | CP8: 08/01/2023 | CQ8: Katherine Ibarra
A9: Oakland/San Francisco/San Jose | B9: UCB Gateway | C9: 210784 | E9: Higher Education | Laboratory / Research | 005 | 004 | F9: 368 | G9: Silverado Contractors | H9: Samantha Chen | I9: Argent Materials, Inc | J9: 8300 Baldwin St, Oakland, CA 94621 | L9: 11/21/2022 | M9: 44866 | N9: 7142674 | O9: Click Here To View | P9: Demolition | Q9: 22.18 | R9: 100.00% | S9: 0.00% | T9: 100.00% | U9: 0.00% | W9: 22.18 | Y9: 22.18 | AC9: 22.18 | BH9: 0.00% | BI9: 0.00% | BJ9: 0.00% | BK9: 0.00% | BS9: 0.00% | BT9: 0.00% | BU9: 0.00% | BV9: 0.00% | CN9: Katherine Ibarra | CP9: 08/01/2023 | CQ9: Katherine Ibarra
A10: Oakland/San Francisco/San Jose | B10: UCB Gateway | C10: 210784 | E10: Higher Education | Laboratory / Research | 005 | 004 | F10: 368 | G10: Silverado Contractors | H10: Samantha Chen | I10: Argent Materials, Inc | J10: 8300 Baldwin St, Oakland, CA 94621 | L10: 11/21/2022 | M10: 44866 | N10: 7142683 | O10: Click Here To View | P10: Demolition | Q10: 18.12 | R10: 100.00% | S10: 0.00% | T10: 100.00% | U10: 0.00% | W10: 18.12 | Y10: 18.12 | AC10: 18.12 | BH10: 0.00% | BI10: 0.00% | BJ10: 0.00% | BK10: 0.00% | BS10: 0.00% | BT10: 0.00% | BU10: 0.00% | BV10: 0.00% | CN10: Katherine Ibarra | CP10: 08/01/2023 | CQ10: Katherine Ibarra
A11: Oakland/San Francisco/San Jose | B11: UCB Gateway | C11: 210784 | E11: Higher Education | Laboratory / Research | 005 | 004 | F11: 368 | G11: Silverado Contractors | H11: Samantha Chen | I11: Argent Materials, Inc | J11: 8300 Baldwin St, Oakland, CA 94621 | L11: 11/21/2022 | M11: 44866 | N11: 7142720 | O11: Click Here To View | P11: Demolition | Q11: 23.07 | R11: 100.00% | S11: 0.00% | T11: 100.00% | U11: 0.00% | W11: 23.07 | Y11: 23.07 | AC11: 23.07 | BH11: 0.00% | BI11: 0.00% | BJ11: 0.00% | BK11: 0.00% | BS11: 0.00% | BT11: 0.00% | BU11: 0.00% | BV11: 0.00% | CN11: Katherine Ibarra | CP11: 08/01/2023 | CQ11: Katherine Ibarra
A12: Oakland/San Francisco/San Jose | B12: UCB Gateway | C12: 210784 | E12: Higher Education | Laboratory / Research | 005 | 004 | F12: 368 | G12: Silverado Contractors | H12: Samantha Chen | I12: Argent Materials, Inc | J12: 8300 Baldwin St, Oakland, CA 94621 | L12: 11/21/2022 | M12: 44866 | N12: 7142734 | O12: Click Here To View | P12: Demolition | Q12: 21.46 | R12: 100.00% | S12: 0.00% | T12: 100.00% | U12: 0.00% | W12: 21.46 | Y12: 21.46 | AC12: 21.46 | BH12: 0.00% | BI12: 0.00% | BJ12: 0.00% | BK12: 0.00% | BS12: 0.00% | BT12: 0.00% | BU12: 0.00% | BV12: 0.00% | CN12: Katherine Ibarra | CP12: 08/01/2023 | CQ12: Katherine Ibarra
A13: Oakland/San Francisco/San Jose | B13: UCB Gateway | C13: 210784 | E13: Higher Education | Laboratory / Research | 005 | 004 | F13: 368 | G13: Silverado Contractors | H13: Samantha Chen | I13: Argent Materials, Inc | J13: 8300 Baldwin St, Oakland, CA 94621 | L13: 11/21/2022 | M13: 44866 | N13: 7142766 | O13: Click Here To View | P13: Demolition | Q13: 12.89 | R13: 100.00% | S13: 0.00% | T13: 100.00% | U13: 0.00% | W13: 12.89 | Y13: 12.89 | AC13: 12.89 | BH13: 0.00% | BI13: 0.00% | BJ13: 0.00% | BK13: 0.00% | BS13: 0.00% | BT13: 0.00% | BU13: 0.00% | BV13: 0.00% | CN13: Katherine Ibarra | CP13: 08/01/2023 | CQ13: Katherine Ibarra
A14: Oakland/San Francisco/San Jose | B14: UCB Gateway | C14: 210784 | E14: Higher Education | Laboratory / Research | 005 | 004 | F14: 368 | G14: Silverado Contractors | H14: Samantha Chen | I14: Argent Materials, Inc | J14: 8300 Baldwin St, Oakland, CA 94621 | L14: 11/21/2022 | M14: 44866 | N14: 7142770 | O14: Click Here To View | P14: Demolition | Q14: 19.48 | R14: 100.00% | S14: 0.00% | T14: 100.00% | U14: 0.00% | W14: 19.48 | Y14: 19.48 | AC14: 19.48 | BH14: 0.00% | BI14: 0.00% | BJ14: 0.00% | BK14: 0.00% | BS14: 0.00% | BT14: 0.00% | BU14: 0.00% | BV14: 0.00% | CN14: Katherine Ibarra | CP14: 08/01/2023 | CQ14: Katherine Ibarra
A15: Oakland/San Francisco/San Jose | B15: UCB Gateway | C15: 210784 | E15: Higher Education | Laboratory / Research | 005 | 004 | F15: 368 | G15: Silverado Contractors | H15: Samantha Chen | I15: Argent Materials, Inc | J15: 8300 Baldwin St, Oakland, CA 94621 | L15: 11/21/2022 | M15: 44866 | N15: 7142802 | O15: Click Here To View | P15: Demolition | Q15: 20.43 | R15: 100.00% | S15: 0.00% | T15: 100.00% | U15: 0.00% | W15: 20.43 | Y15: 20.43 | AC15: 20.43 | BH15: 0.00% | BI15: 0.00% | BJ15: 0.00% | BK15: 0.00% | BS15: 0.00% | BT15: 0.00% | BU15: 0.00% | BV15: 0.00% | CN15: Katherine Ibarra | CP15: 08/01/2023 | CQ15: Katherine Ibarra
... A29: Oakland/San Francisco/San Jose | B29: UCB Gateway | C29: 210784 | E29: Higher Education | Laboratory / Research | 005 | 004 | F29: 368 | G29: Silverado Contractors | H29: Samantha Chen | I29: Argent Materials, Inc | J29: 8300 Baldwin St, Oakland, CA 94621 | L29: 11/23/2022 | M29: 44866 | N29: 7143210 | O29: Click Here To View | P29: Demolition | Q29: 23.57 | R29: 100.00% | S29: 0.00% | T29: 100.00% | U29: 0.00% | W29: 23.57 | Y29: 23.57 | AC29: 23.57 | BH29: 0.00% | BI29: 0.00% | BJ29: 0.00% | BK29: 0.00% | BS29: 0.00% | BT29: 0.00% | BU29: 0.00% | BV29: 0.00% | CN29: Katherine Ibarra | CP29: 08/01/2023 | CQ29: Katherine Ibarra
A30: Oakland/San Francisco/San Jose | B30: UCB Gateway | C30: 210784 | E30: Higher Education | Laboratory / Research | 005 | 004 | F30: 368 | G30: Silverado Contractors | H30: Samantha Chen | I30: Schnitzer Steel - Oakland | J30: 1101 Embarcadero West, Oakland CA, Oakland, CA 94607 | L30: 11/17/2022 | M30: 44866 | N30: TABHVS | O30: Click Here To View | P30: Demolition | Q30: 3.52 | R30: 100.00% | S30: 0.00% | T30: 100.00% | U30: 0.00% | W30: 3.52 | Y30: 3.52 | AF30: 3.52 | BH30: 0.00% | BI30: 0.00% | BJ30: 0.00% | BK30: 0.00% | BS30: 0.00% | BT30: 0.00% | BU30: 0.00% | BV30: 0.00% | CN30: Katherine Ibarra | CP30: 08/01/2023 | CQ30: Katherine Ibarra
A31: Oakland/San Francisco/San Jose | B31: UCB Gateway | C31: 210784 | E31: Higher Education | Laboratory / Research | 005 | 004 | F31: 368 | G31: Certified Blue Recycling | H31: S Barron | I31: Certified Blue Recycling Without ADC (LEED) | J31: 2075 Williams St, San Leandro, CA 94577 | L31: 11/30/2022 | M31: 44866 | N31: 82097 | O31: Click Here To View | P31: Demolition | Q31: 1.08 | R31: 30.56% | S31: 0.00% | T31: 30.56% | U31: 69.44% | W31: 0.33 | X31: 0.75 | Y31: 1.08 | Z31: 0.41 | AG31: 0.33 | AI31: 0.34 | BH31: 0.00% | BI31: 0.00% | BJ31: 0.00% | BK31: 0.00% | BS31: 0.00% | BT31: 0.00% | BU31: 0.00% | BV31: 0.00% | CN31: Mahek Pathak | CP31: 02/21/2023 | CQ31: Mahek Pathak
A32: Oakland/San Francisco/San Jose | B32: UCB Gateway | C32: 210784 | E32: Higher Education | Laboratory / Research | 005 | 004 | F32: 368 | G32: Silverado Contractors | H32: Samantha Chen | I32: Schnitzer Steel - Oakland | J32: 1101 Embarcadero West, Oakland CA, Oakland, CA 94607 | L32: 12/14/2022 | M32: 44896 | N32: TAEIPJ | O32: Click Here To View | P32: Demolition | Q32: 8.92 | R32: 100.00% | S32: 0.00% | T32: 100.00% | U32: 0.00% | W32: 8.92 | Y32: 8.92 | AF32: 8.92 | BH32: 0.00% | BI32: 0.00% | BJ32: 0.00% | BK32: 0.00% | BS32: 0.00% | BT32: 0.00% | BU32: 0.00% | BV32: 0.00% | CN32: Katherine Ibarra | CP32: 08/01/2023 | CQ32: Katherine Ibarra
A33: Oakland/San Francisco/San Jose | B33: UCB Gateway | C33: 210784 | E33: Higher Education | Laboratory / Research | 005 | 004 | F33: 368 | G33: Certified Blue Recycling | H33: S Barron | I33: Certified Blue Recycling Without ADC (LEED) | J33: 2075 Williams St, San Leandro, CA 94577 | L33: 12/22/2022 | M33: 44896 | N33: 82815 | O33: Click Here To View | P33: Demolition | Q33: 0.8848 | R33: 31.65% | S33: 0.00% | T33: 31.65% | U33: 68.35% | W33: 0.28 | X33: 0.6048 | Y33: 0.8848 | Z33: 0.3348 | AG33: 0.28 | AI33: 0.27 | BH33: 0.00% | BI33: 0.00% | BJ33: 0.00% | BK33: 0.00% | BS33: 0.00% | BT33: 0.00% | BU33: 0.00% | BV33: 0.00% | CN33: Mahek Pathak | CP33: 02/21/2023 | CQ33: Mahek Pathak
A34: Oakland/San Francisco/San Jose | B34: UCB Gateway | C34: 210784 | E34: Higher Education | Laboratory / Research | 005 | 004 | F34: 368 | G34: Certified Blue Recycling | H34: S Barron | I34: Certified Blue Recycling Without ADC (LEED) | J34: 2075 Williams St, San Leandro, CA 94577 | L34: 12/01/2022 | M34: 44896 | N34: 82137 | O34: Click Here To View | P34: Demolition | Q34: 1.31 | R34: 100.00% | S34: 0.00% | T34: 100.00% | U34: 0.00% | W34: 1.31 | Y34: 1.31 | BE34: 1.31 | BH34: 0.00% | BI34: 0.00% | BJ34: 0.00% | BK34: 0.00% | BS34: 0.00% | BT34: 0.00% | BU34: 0.00% | BV34: 0.00% | CN34: Mahek Pathak | CP34: 02/21/2023 | CQ34: Mahek Pathak
A35: Oakland/San Francisco/San Jose | B35: UCB Gateway | C35: 210784 | E35: Higher Education | Laboratory / Research | 005 | 004 | F35: 368 | G35: Silverado Contractors | H35: Samantha Chen | I35: Argent Materials, Inc | J35: 8300 Baldwin St, Oakland, CA 94621 | L35: 04/18/2023 | M35: 45017 | N35: 7159481 | O35: Click Here To View | P35: Demolition | Q35: 13.37 | R35: 100.00% | S35: 0.00% | T35: 100.00% | U35: 0.00% | W35: 13.37 | Y35: 13.37 | AC35: 13.37 | BH35: 0.00% | BI35: 0.00% | BJ35: 0.00% | BK35: 0.00% | BS35: 0.00% | BT35: 0.00% | BU35: 0.00% | BV35: 0.00% | CN35: Katherine Ibarra | CP35: 08/02/2023 | CQ35: Katherine Ibarra
A36: Oakland/San Francisco/San Jose | B36: UCB Gateway | C36: 210784 | E36: Higher Education | Laboratory / Research | 005 | 004 | F36: 368 | G36: Silverado Contractors | H36: Samantha Chen | I36: Argent Materials, Inc | J36: 8300 Baldwin St, Oakland, CA 94621 | L36: 04/18/2023 | M36: 45017 | N36: 7159445 | O36: Click Here To View | P36: Demolition | Q36: 21.53 | R36: 100.00% | S36: 0.00% | T36: 100.00% | U36: 0.00% | W36: 21.53 | Y36: 21.53 | AC36: 21.53 | BH36: 0.00% | BI36: 0.00% | BJ36: 0.00% | BK36: 0.00% | BS36: 0.00% | BT36: 0.00% | BU36: 0.00% | BV36: 0.00% | CN36: Katherine Ibarra | CP36: 08/02/2023 | CQ36: Katherine Ibarra
A37: Oakland/San Francisco/San Jose | B37: UCB Gateway | C37: 210784 | E37: Higher Education | Laboratory / Research | 005 | 004 | F37: 368 | G37: Silverado Contractors | H37: Samantha Chen | I37: Argent Materials, Inc | J37: 8300 Baldwin St, Oakland, CA 94621 | L37: 04/18/2023 | M37: 45017 | N37: 7159451 | O37: Click Here To View | P37: Demolition | Q37: 22.82 | R37: 100.00% | S37: 0.00% | T37: 100.00% | U37: 0.00% | W37: 22.82 | Y37: 22.82 | AC37: 22.82 | BH37: 0.00% | BI37: 0.00% | BJ37: 0.00% | BK37: 0.00% | BS37: 0.00% | BT37: 0.00% | BU37: 0.00% | BV37: 0.00% | CN37: Katherine Ibarra | CP37: 08/02/2023 | CQ37: Katherine Ibarra
A38: Oakland/San Francisco/San Jose | B38: UCB Gateway | C38: 210784 | E38: Higher Education | Laboratory / Research | 005 | 004 | F38: 368 | G38: Silverado Contractors | H38: Samantha Chen | I38: Argent Materials, Inc | J38: 8300 Baldwin St, Oakland, CA 94621 | L38: 04/18/2023 | M38: 45017 | N38: 7159462 | O38: Click Here To View | P38: Demolition | Q38: 14.22 | R38: 100.00% | S38: 0.00% | T38: 100.00% | U38: 0.00% | W38: 14.22 | Y38: 14.22 | AC38: 14.22 | BH38: 0.00% | BI38: 0.00% | BJ38: 0.00% | BK38: 0.00% | BS38: 0.00% | BT38: 0.00% | BU38: 0.00% | BV38: 0.00% | CN38: Katherine Ibarra | CP38: 08/02/2023 | CQ38: Katherine Ibarra
A39: Oakland/San Francisco/San Jose | B39: UCB Gateway | C39: 210784 | E39: Higher Education | Laboratory / Research | 005 | 004 | F39: 368 | G39: Silverado Contractors | H39: Samantha Chen | I39: Excess Recovery, INC. | J39: 1801 Evans Avenue, San Francisco, CA 94124, San Francisco, CA 94124 | L39: 04/10/2023 | M39: 45017 | N39: 40293 | O39: Click Here To View | P39: Demolition | Q39: 5.9 | R39: 71.00% | S39: 0.00% | T39: 71.00% | U39: 29.00% | W39: 4.189 | X39: 1.711 | Y39: 5.9 | AY39: 4.189 | BD39: 1.711 | BH39: 0.00% | BI39: 0.00% | BJ39: 0.00% | BK39: 0.00% | BS39: 0.00% | BT39: 0.00% | BU39: 0.00% | BV39: 0.00% | CN39: Katherine Ibarra | CP39: 08/02/2023 | CQ39: Katherine Ibarra
A40: Oakland/San Francisco/San Jose | B40: UCB Gateway | C40: 210784 | E40: Higher Education | Laboratory / Research | 005 | 004 | F40: 368 | G40: Silverado Contractors | H40: Samantha Chen | I40: Excess Recovery, INC. | J40: 1801 Evans Avenue, San Francisco, CA 94124, San Francisco, CA 94124 | L40: 04/20/2023 | M40: 45017 | N40: 39843 | O40: Click Here To View | P40: Demolition | Q40: 10.05 | R40: 71.00% | S40: 0.00% | T40: 71.00% | U40: 29.00% | W40: 7.1355 | X40: 2.9145 | Y40: 10.05 | AY40: 7.1355 | BD40: 2.9145 | BH40: 0.00% | BI40: 0.00% | BJ40: 0.00% | BK40: 0.00% | BS40: 0.00% | BT40: 0.00% | BU40: 0.00% | BV40: 0.00% | CN40: Katherine Ibarra | CP40: 08/02/2023 | CQ40: Katherine Ibarra
A41: Oakland/San Francisco/San Jose | B41: UCB Gateway | C41: 210784 | E41: Higher Education | Laboratory / Research | 005 | 004 | F41: 368 | G41: Silverado Contractors | H41: Samantha Chen | I41: Argent Materials, Inc | J41: 8300 Baldwin St, Oakland, CA 94621 | L41: 05/11/2023 | M41: 45047 | N41: 7163221 | O41: Click Here To View | P41: Demolition | Q41: 19.28 | R41: 100.00% | S41: 0.00% | T41: 100.00% | U41: 0.00% | W41: 19.28 | Y41: 19.28 | AC41: 19.28 | BH41: 0.00% | BI41: 0.00% | BJ41: 0.00% | BK41: 0.00% | BS41: 0.00% | BT41: 0.00% | BU41: 0.00% | BV41: 0.00% | CN41: Katherine Ibarra | CP41: 08/02/2023 | CQ41: Katherine Ibarra
A42: Oakland/San Francisco/San Jose | B42: UCB Gateway | C42: 210784 | E42: Higher Education | Laboratory / Research | 005 | 004 | F42: 368 | G42: Silverado Contractors | H42: Samantha Chen | I42: Argent Materials, Inc | J42: 8300 Baldwin St, Oakland, CA 94621 | L42: 05/22/2023 | M42: 45047 | N42: 7164757 | O42: Click Here To View | P42: Demolition | Q42: 18.69 | R42: 100.00% | S42: 0.00% | T42: 100.00% | U42: 0.00% | W42: 18.69 | Y42: 18.69 | AC42: 18.69 | BH42: 0.00% | BI42: 0.00% | BJ42: 0.00% | BK42: 0.00% | BS42: 0.00% | BT42: 0.00% | BU42: 0.00% | BV42: 0.00% | CN42: Katherine Ibarra | CP42: 08/02/2023 | CQ42: Katherine Ibarra
A43: Oakland/San Francisco/San Jose | B43: UCB Gateway | C43: 210784 | E43: Higher Education | Laboratory / Research | 005 | 004 | F43: 368 | G43: Silverado Contractors | H43: Samantha Chen | I43: Argent Materials, Inc | J43: 8300 Baldwin St, Oakland, CA 94621 | L43: 05/22/2023 | M43: 45047 | N43: 7164758 | O43: Click Here To View | P43: Demolition | Q43: 19.13 | R43: 100.00% | S43: 0.00% | T43: 100.00% | U43: 0.00% | W43: 19.13 | Y43: 19.13 | AC43: 19.13 | BH43: 0.00% | BI43: 0.00% | BJ43: 0.00% | BK43: 0.00% | BS43: 0.00% | BT43: 0.00% | BU43: 0.00% | BV43: 0.00% | CN43: Katherine Ibarra | CP43: 08/02/2023 | CQ43: Katherine Ibarra
A44: Oakland/San Francisco/San Jose | B44: UCB Gateway | C44: 210784 | E44: Higher Education | Laboratory / Research | 005 | 004 | F44: 368 | G44: Silverado Contractors | H44: Samantha Chen | I44: Argent Materials, Inc | J44: 8300 Baldwin St, Oakland, CA 94621 | L44: 05/22/2023 | M44: 45047 | N44: 7164762 | O44: Click Here To View | P44: Demolition | Q44: 21.84 | R44: 100.00% | S44: 0.00% | T44: 100.00% | U44: 0.00% | W44: 21.84 | Y44: 21.84 | AC44: 21.84 | BH44: 0.00% | BI44: 0.00% | BJ44: 0.00% | BK44: 0.00% | BS44: 0.00% | BT44: 0.00% | BU44: 0.00% | BV44: 0.00% | CN44: Katherine Ibarra | CP44: 08/02/2023 | CQ44: Katherine Ibarra
A45: Oakland/San Francisco/San Jose | B45: UCB Gateway | C45: 210784 | E45: Higher Education | Laboratory / Research | 005 | 004 | F45: 368 | G45: Silverado Contractors | H45: Samantha Chen | I45: Argent Materials, Inc | J45: 8300 Baldwin St, Oakland, CA 94621 | L45: 05/22/2023 | M45: 45047 | N45: 7164786 | O45: Click Here To View | P45: Demolition | Q45: 22.75 | R45: 100.00% | S45: 0.00% | T45: 100.00% | U45: 0.00% | W45: 22.75 | Y45: 22.75 | AC45: 22.75 | BH45: 0.00% | BI45: 0.00% | BJ45: 0.00% | BK45: 0.00% | BS45: 0.00% | BT45: 0.00% | BU45: 0.00% | BV45: 0.00% | CN45: Katherine Ibarra | CP45: 08/02/2023 | CQ45: Katherine Ibarra
A46: Oakland/San Francisco/San Jose | B46: UCB Gateway | C46: 210784 | E46: Higher Education | Laboratory / Research | 005 | 004 | F46: 368 | G46: Silverado Contractors | H46: Samantha Chen | I46: Argent Materials, Inc | J46: 8300 Baldwin St, Oakland, CA 94621 | L46: 05/22/2023 | M46: 45047 | N46: 7164787 | O46: Click Here To View | P46: Demolition | Q46: 23.16 | R46: 100.00% | S46: 0.00% | T46: 100.00% | U46: 0.00% | W46: 23.16 | Y46: 23.16 | AC46: 23.16 | BH46: 0.00% | BI46: 0.00% | BJ46: 0.00% | BK46: 0.00% | BS46: 0.00% | BT46: 0.00% | BU46: 0.00% | BV46: 0.00% | CN46: Katherine Ibarra | CP46: 08/02/2023 | CQ46: Katherine Ibarra
A47: Oakland/San Francisco/San Jose | B47: UCB Gateway | C47: 210784 | E47: Higher Education | Laboratory / Research | 005 | 004 | F47: 368 | G47: Silverado Contractors | H47: Samantha Chen | I47: Argent Materials, Inc | J47: 8300 Baldwin St, Oakland, CA 94621 | L47: 05/22/2023 | M47: 45047 | N47: 7164789 | O47: Click Here To View | P47: Demolition | Q47: 22.2 | R47: 100.00% | S47: 0.00% | T47: 100.00% | U47: 0.00% | W47: 22.2 | Y47: 22.2 | AC47: 22.2 | BH47: 0.00% | BI47: 0.00% | BJ47: 0.00% | BK47: 0.00% | BS47: 0.00% | BT47: 0.00% | BU47: 0.00% | BV47: 0.00% | CN47: Katherine Ibarra | CP47: 08/02/2023 | CQ47: Katherine Ibarra
A48: Oakland/San Francisco/San Jose | B48: UCB Gateway | C48: 210784 | E48: Higher Education | Laboratory / Research | 005 | 004 | F48: 368 | G48: Silverado Contractors | H48: Samantha Chen | I48: Argent Materials, Inc | J48: 8300 Baldwin St, Oakland, CA 94621 | L48: 05/22/2023 | M48: 45047 | N48: 7164814 | O48: Click Here To View | P48: Demolition | Q48: 21.12 | R48: 100.00% | S48: 0.00% | T48: 100.00% | U48: 0.00% | W48: 21.12 | Y48: 21.12 | AC48: 21.12 | BH48: 0.00% | BI48: 0.00% | BJ48: 0.00% | BK48: 0.00% | BS48: 0.00% | BT48: 0.00% | BU48: 0.00% | BV48: 0.00% | CN48: Katherine Ibarra | CP48: 08/02/2023 | CQ48: Katherine Ibarra
A49: Oakland/San Francisco/San Jose | B49: UCB Gateway | C49: 210784 | E49: Higher Education | Laboratory / Research | 005 | 004 | F49: 368 | G49: Silverado Contractors | H49: Samantha Chen | I49: Argent Materials, Inc | J49: 8300 Baldwin St, Oakland, CA 94621 | L49: 05/22/2023 | M49: 45047 | N49: 7164816 | O49: Click Here To View | P49: Demolition | Q49: 22.65 | R49: 100.00% | S49: 0.00% | T49: 100.00% | U49: 0.00% | W49: 22.65 | Y49: 22.65 | AC49: 22.65 | BH49: 0.00% | BI49: 0.00% | BJ49: 0.00% | BK49: 0.00% | BS49: 0.00% | BT49: 0.00% | BU49: 0.00% | BV49: 0.00% | CN49: Katherine Ibarra | CP49: 08/02/2023 | CQ49: Katherine Ibarra
A50: Oakland/San Francisco/San Jose | B50: UCB Gateway | C50: 210784 | E50: Higher Education | Laboratory / Research | 005 | 004 | F50: 368 | G50: Silverado Contractors | H50: Samantha Chen | I50: Argent Materials, Inc | J50: 8300 Baldwin St, Oakland, CA 94621 | L50: 05/22/2023 | M50: 45047 | N50: 7164818 | O50: Click Here To View | P50: Demolition | Q50: 16.88 | R50: 100.00% | S50: 0.00% | T50: 100.00% | U50: 0.00% | W50: 16.88 | Y50: 16.88 | AC50: 16.88 | BH50: 0.00% | BI50: 0.00% | BJ50: 0.00% | BK50: 0.00% | BS50: 0.00% | BT50: 0.00% | BU50: 0.00% | BV50: 0.00% | CN50: Katherine Ibarra | CP50: 08/02/2023 | CQ50: Katherine Ibarra
A51: Oakland/San Francisco/San Jose | B51: UCB Gateway | C51: 210784 | E51: Higher Education | Laboratory / Research | 005 | 004 | F51: 368 | G51: Silverado Contractors | H51: Samantha Chen | I51: Argent Materials, Inc | J51: 8300 Baldwin St, Oakland, CA 94621 | L51: 05/22/2023 | M51: 45047 | N51: 7164863 | O51: Click Here To View | P51: Demolition | Q51: 18.21 | R51: 100.00% | S51: 0.00% | T51: 100.00% | U51: 0.00% | W51: 18.21 | Y51: 18.21 | AC51: 18.21 | BH51: 0.00% | BI51: 0.00% | BJ51: 0.00% | BK51: 0.00% | BS51: 0.00% | BT51: 0.00% | BU51: 0.00% | BV51: 0.00% | CN51: Katherine Ibarra | CP51: 08/02/2023 | CQ51: Katherine Ibarra
A52: Oakland/San Francisco/San Jose | B52: UCB Gateway | C52: 210784 | E52: Higher Education | Laboratory / Research | 005 | 004 | F52: 368 | G52: Silverado Contractors | H52: Samantha Chen | I52: Argent Materials, Inc | J52: 8300 Baldwin St, Oakland, CA 94621 | L52: 05/22/2023 | M52: 45047 | N52: 7164864 | O52: Click Here To View | P52: Demolition | Q52: 20.15 | R52: 100.00% | S52: 0.00% | T52: 100.00% | U52: 0.00% | W52: 20.15 | Y52: 20.15 | AC52: 20.15 | BH52: 0.00% | BI52: 0.00% | BJ52: 0.00% | BK52: 0.00% | BS52: 0.00% | BT52: 0.00% | BU52: 0.00% | BV52: 0.00% | CN52: Katherine Ibarra | CP52: 08/02/2023 | CQ52: Katherine Ibarra
... A109: Oakland/San Francisco/San Jose | B109: UCB Gateway | C109: 210784 | E109: Higher Education | Laboratory / Research | 005 | 004 | F109: 368 | G109: Silverado Contractors | H109: Samantha Chen | I109: Argent Materials, Inc | J109: 8300 Baldwin St, Oakland, CA 94621 | L109: 05/31/2023 | M109: 45047 | N109: 7166349 | O109: Click Here To View | P109: Demolition | Q109: 18.87 | R109: 100.00% | S109: 0.00% | T109: 100.00% | U109: 0.00% | W109: 18.87 | Y109: 18.87 | AC109: 18.87 | BH109: 0.00% | BI109: 0.00% | BJ109: 0.00% | BK109: 0.00% | BS109: 0.00% | BT109: 0.00% | BU109: 0.00% | BV109: 0.00% | CN109: Katherine Ibarra | CP109: 08/02/2023 | CQ109: Katherine Ibarra
A110: Oakland/San Francisco/San Jose | B110: UCB Gateway | C110: 210784 | E110: Higher Education | Laboratory / Research | 005 | 004 | F110: 368 | G110: Silverado Contractors | H110: Samantha Chen | I110: Schnitzer Steel - Oakland | J110: 1101 Embarcadero West, Oakland CA, Oakland, CA 94607 | L110: 05/10/2023 | M110: 45047 | N110: TAXPLY | O110: Click Here To View | P110: Demolition | Q110: 3.29 | R110: 100.00% | S110: 0.00% | T110: 100.00% | U110: 0.00% | W110: 3.29 | Y110: 3.29 | AF110: 3.29 | BH110: 0.00% | BI110: 0.00% | BJ110: 0.00% | BK110: 0.00% | BS110: 0.00% | BT110: 0.00% | BU110: 0.00% | BV110: 0.00% | CN110: Katherine Ibarra | CP110: 08/01/2023 | CQ110: Katherine Ibarra
...

Sheet Entire Project Overiew
A1: GATEWAY CONSTRUCTION TRUE COST BENEFIT ANALYSIS (for entire project)
A3: Total Cost Savings with TRUE
A4: Total Costs (pursuing TRUE) | D4: =B34+H42 -> 5569112.9
A5: Total Costs (not pursuing TRUE) | D5: =H34+B42 -> 7419040.3
A6: Total Cost Savings from source seperating | D6: =D5-D4 -> 1849927.3
A8: Gateway Hauling Metrics with TRUE (>90% Diversion) | G8: Typical Hauling Metrics without TRUE (no source seperation) | M8: Hauling Cost References
A9: Fixed Costs | G9: Fixed Costs | M9: Category | N9: Payment or Rebate | O9: Fixed Haul Fee | P9: Disposal Fee | Q9: Disposal Unit | R9: Disposal Fee (tons)
A10: Number of total hauls | B10: Fixed Haul fee | C10: Total fixed hauling fee | G10: Number of total hauls | H10: Fixed Haul fee | I10: Total fixed hauling fee | M10: Municipal Waste Services:
A11: =COUNTA('Raw Data'!H11:H1217) -> 1207 | B11: =O11 -> 545 | C11: =A11*B11 -> 657815 | G11: =COUNTA('Raw Data'!N11:N1217) -> 1207 | H11: =O11 -> 545 | I11: {=(G11-(COUNT(_xlfn._xlws.FILTER('Raw Data'!AL11:AL1217,'Raw Data'!AL11:AL1217*-$R$18>$B$11)))-(COUNT(_xlfn._xlws.FILTER('Raw Data'!AH11:AH1217,'Raw Data'!AH11:AH1217*-$R$19>$B$11))))*H11} -> 657815 | M11: MSW Trash | N11: Payment | O11: 545 | P11: 50 | Q11: 1 yd Pull | R11: 100
M12: Recycling | N12: Payment | O12: 545 | P12: 50 | Q12: 1 yd Pull | R12: 100
A13: Variable Costs | G13: Variable Costs | M13: Compost | N13: Payment | O13: 545 | P13: 50 | Q13: 1 yd Pull | R13: 100
A14: Material | B14: Category | C14: Disposal Fee (tons) | D14: Tons | E14: Total Cost | G14: Material | H14: Category | I14: Disposal Fee (tons) | J14: Tons | K14: Total Cost | M14: C&D Waste Services:
A15: Alternate Daily Cover (ADC) | B15: =M15 -> Mixed C&D | C15: {=_xlfn.XLOOKUP(B15,_xlfn.VSTACK($M$11:$M$13,$M$15:$M$21),_xlfn.VSTACK($R$11:$R$13,$R$15:$R$21))} -> 100 | D15: 354.4339 | E15: =C15*D15 -> 35443.39 | G15: Alternate Daily Cover (ADC) | H15: =$M$15 -> Mixed C&D | I15: {=_xlfn.XLOOKUP(H15,_xlfn.VSTACK($M$11:$M$13,$M$15:$M$21),_xlfn.VSTACK($R$11:$R$13,$R$15:$R$21))} -> 100 | J15: 354.4339 | K15: =I15*J15 -> 35443.39 | M15: Mixed C&D | N15: Payment | O15: 545 | P15: 100 | Q15: Tons | R15: =P15 -> 100
A16: Asphalt - Pavement & Grinding | B16: =M20 -> Concrete & dirt | C16: {=_xlfn.XLOOKUP(B16,_xlfn.VSTACK($M$11:$M$13,$M$15:$M$21),_xlfn.VSTACK($R$11:$R$13,$R$15:$R$21))} -> 73 | D16: 380.4215 | E16: =C16*D16 -> 27770.769 | G16: Asphalt - Pavement & Grinding | H16: =$M$15 -> Mixed C&D | I16: {=_xlfn.XLOOKUP(H16,_xlfn.VSTACK($M$11:$M$13,$M$15:$M$21),_xlfn.VSTACK($R$11:$R$13,$R$15:$R$21))} -> 100 | J16: 380.4215 | K16: =I16*J16 -> 38042.15 | M16: Wood | N16: Payment | O16: 545 | P16: 85 | Q16: Tons | R16: =P16 -> 85
A17: Cardboard & Paper Products | B17: =M19 -> Cardboard | C17: {=_xlfn.XLOOKUP(B17,_xlfn.VSTACK($M$11:$M$13,$M$15:$M$21),_xlfn.VSTACK($R$11:$R$13,$R$15:$R$21))} -> -50 | D17: 10.009 | E17: {=((SUMPRODUCT((('Raw Data'!AB11:AB1217*-$R$19)>$B$11)*'Raw Data'!AB11:AB1217))*$R$19)+(COUNT(_xlfn._xlws.FILTER('Raw Data'!AB11:AB1217,'Raw Data'!AB11:AB1217*-$R$19>$B$11))*B11)} -> 0 | G17: Cardboard & Paper Products | H17: =$M$15 -> Mixed C&D | I17: {=_xlfn.XLOOKUP(H17,_xlfn.VSTACK($M$11:$M$13,$M$15:$M$21),_xlfn.VSTACK($R$11:$R$13,$R$15:$R$21))} -> 100 | J17: 10.009 | K17: =I17*J17 -> 1000.9 | M17: Drywall | N17: Payment | O17: 545 | P17: 55 | Q17: Tons | R17: =P17 -> 55
A18: Concrete | B18: =M20 -> Concrete & dirt | C18: {=_xlfn.XLOOKUP(B18,_xlfn.VSTACK($M$11:$M$13,$M$15:$M$21),_xlfn.VSTACK($R$11:$R$13,$R$15:$R$21))} -> 73 | D18: 4903.8497 | E18: =C18*D18 -> 357981.03 | G18: Concrete | H18: =$M$15 -> Mixed C&D | I18: {=_xlfn.XLOOKUP(H18,_xlfn.VSTACK($M$11:$M$13,$M$15:$M$21),_xlfn.VSTACK($R$11:$R$13,$R$15:$R$21))} -> 100 | J18: 4903.8497 | K18: =I18*J18 -> 490384.97 | M18: Metal | N18: Rebate | O18: 545 | P18: -0.03 | Q18: pound | R18: =P18*2000 -> -60
A19: Drywall - Demo & painted | B19: =M17 -> Drywall | C19: {=_xlfn.XLOOKUP(B19,_xlfn.VSTACK($M$11:$M$13,$M$15:$M$21),_xlfn.VSTACK($R$11:$R$13,$R$15:$R$21))} -> 55 | D19: 20.45 | E19: =C19*D19 -> 1124.75 | G19: Drywall - Demo & painted | H19: =$M$15 -> Mixed C&D | I19: {=_xlfn.XLOOKUP(H19,_xlfn.VSTACK($M$11:$M$13,$M$15:$M$21),_xlfn.VSTACK($R$11:$R$13,$R$15:$R$21))} -> 100 | J19: 20.45 | K19: =I19*J19 -> 2045 | M19: Cardboard | N19: Rebate | O19: 545 | P19: -50 | Q19: Tons | R19: =P19 -> -50
A20: Metal | B20: =M18 -> Metal | C20: {=_xlfn.XLOOKUP(B20,_xlfn.VSTACK($M$11:$M$13,$M$15:$M$21),_xlfn.VSTACK($R$11:$R$13,$R$15:$R$21))} -> -60 | D20: 244.367 | E20: {=((SUMPRODUCT((('Raw Data'!AF11:AF1217*-$R$18)>$B$11)*'Raw Data'!AF11:AF1217))*$R$18)+(COUNT(_xlfn._xlws.FILTER('Raw Data'!AF11:AF1217,'Raw Data'!AF11:AF1217*-$R$18>$B$11))*B11)} -> -9941 | G20: Metal | H20: =$M$15 -> Mixed C&D | I20: {=_xlfn.XLOOKUP(H20,_xlfn.VSTACK($M$11:$M$13,$M$15:$M$21),_xlfn.VSTACK($R$11:$R$13,$R$15:$R$21))} -> 100 | J20: 244.367 | K20: =I20*J20 -> 24436.7 | M20: Concrete & dirt | N20: Payment | O20: 545 | P20: 730 | Q20: 13 yd Box | R20: =P20/10 -> 73
A21: Mixed Recyclables | B21: =M15 -> Mixed C&D | C21: {=_xlfn.XLOOKUP(B21,_xlfn.VSTACK($M$11:$M$13,$M$15:$M$21),_xlfn.VSTACK($R$11:$R$13,$R$15:$R$21))} -> 100 | D21: 302.3215 | E21: =C21*D21 -> 30232.15 | G21: Mixed Recyclables | H21: =$M$15 -> Mixed C&D | I21: {=_xlfn.XLOOKUP(H21,_xlfn.VSTACK($M$11:$M$13,$M$15:$M$21),_xlfn.VSTACK($R$11:$R$13,$R$15:$R$21))} -> 100 | J21: 302.3215 | K21: =I21*J21 -> 30232.15 | M21: Dirty concrete | N21: Payment | O21: 545 | P21: 850 | Q21: 13 yd Box | R21: =P21/10 -> 85
A22: Plastics & Plastic Packaging Materials | B22: =M12 -> Recycling | C22: {=_xlfn.XLOOKUP(B22,_xlfn.VSTACK($M$11:$M$13,$M$15:$M$21),_xlfn.VSTACK($R$11:$R$13,$R$15:$R$21))} -> 100 | D22: 3.616 | E22: =C22*D22 -> 361.6 | G22: Plastics & Plastic Packaging Materials | H22: =$M$15 -> Mixed C&D | I22: {=_xlfn.XLOOKUP(H22,_xlfn.VSTACK($M$11:$M$13,$M$15:$M$21),_xlfn.VSTACK($R$11:$R$13,$R$15:$R$21))} -> 100 | J22: 3.616 | K22: =I22*J22 -> 361.6
A23: Waste (Trash) | B23: =M15 -> Mixed C&D | C23: {=_xlfn.XLOOKUP(B23,_xlfn.VSTACK($M$11:$M$13,$M$15:$M$21),_xlfn.VSTACK($R$11:$R$13,$R$15:$R$21))} -> 100 | D23: 288.3466 | E23: =C23*D23 -> 28834.66 | G23: Waste (Trash) | H23: =$M$15 -> Mixed C&D | I23: {=_xlfn.XLOOKUP(H23,_xlfn.VSTACK($M$11:$M$13,$M$15:$M$21),_xlfn.VSTACK($R$11:$R$13,$R$15:$R$21))} -> 100 | J23: 288.3466 | K23: =I23*J23 -> 28834.66
A24: Compost | B24: =M13 -> Compost | C24: {=_xlfn.XLOOKUP(B24,_xlfn.VSTACK($M$11:$M$13,$M$15:$M$21),_xlfn.VSTACK($R$11:$R$13,$R$15:$R$21))} -> 100 | D24: 0.75 | E24: =C24*D24 -> 75 | G24: Compost | H24: =$M$15 -> Mixed C&D | I24: {=_xlfn.XLOOKUP(H24,_xlfn.VSTACK($M$11:$M$13,$M$15:$M$21),_xlfn.VSTACK($R$11:$R$13,$R$15:$R$21))} -> 100 | J24: 0.75 | K24: =I24*J24 -> 75
A25: Drywall - Clean/Unpainted | B25: =M17 -> Drywall | C25: {=_xlfn.XLOOKUP(B25,_xlfn.VSTACK($M$11:$M$13,$M$15:$M$21),_xlfn.VSTACK($R$11:$R$13,$R$15:$R$21))} -> 55 | D25: 939.57 | E25: =C25*D25 -> 51676.35 | G25: Drywall - Clean/Unpainted | H25: =$M$15 -> Mixed C&D | I25: {=_xlfn.XLOOKUP(H25,_xlfn.VSTACK($M$11:$M$13,$M$15:$M$21),_xlfn.VSTACK($R$11:$R$13,$R$15:$R$21))} -> 100 | J25: 939.57 | K25: =I25*J25 -> 93957
A26: Miscellaneous Debris | B26: =M15 -> Mixed C&D | C26: {=_xlfn.XLOOKUP(B26,_xlfn.VSTACK($M$11:$M$13,$M$15:$M$21),_xlfn.VSTACK($R$11:$R$13,$R$15:$R$21))} -> 100 | D26: 24.3426 | E26: =C26*D26 -> 2434.26 | G26: Miscellaneous Debris | H26: =$M$15 -> Mixed C&D | I26: {=_xlfn.XLOOKUP(H26,_xlfn.VSTACK($M$11:$M$13,$M$15:$M$21),_xlfn.VSTACK($R$11:$R$13,$R$15:$R$21))} -> 100 | J26: 24.3426 | K26: =I26*J26 -> 2434.26
A27: Trash Sorted for Recovery | B27: =M11 -> MSW Trash | C27: {=_xlfn.XLOOKUP(B27,_xlfn.VSTACK($M$11:$M$13,$M$15:$M$21),_xlfn.VSTACK($R$11:$R$13,$R$15:$R$21))} -> 100 | D27: 9.1002 | E27: =C27*D27 -> 910.02 | G27: Trash Sorted for Recovery | H27: =$M$15 -> Mixed C&D | I27: {=_xlfn.XLOOKUP(H27,_xlfn.VSTACK($M$11:$M$13,$M$15:$M$21),_xlfn.VSTACK($R$11:$R$13,$R$15:$R$21))} -> 100 | J27: 9.1002 | K27: =I27*J27 -> 910.02
A28: Wood - Clean | B28: =M16 -> Wood | C28: {=_xlfn.XLOOKUP(B28,_xlfn.VSTACK($M$11:$M$13,$M$15:$M$21),_xlfn.VSTACK($R$11:$R$13,$R$15:$R$21))} -> 85 | D28: 751.4749 | E28: =C28*D28 -> 63875.366 | G28: Wood - Clean | H28: =$M$15 -> Mixed C&D | I28: {=_xlfn.XLOOKUP(H28,_xlfn.VSTACK($M$11:$M$13,$M$15:$M$21),_xlfn.VSTACK($R$11:$R$13,$R$15:$R$21))} -> 100 | J28: 751.4749 | K28: =I28*J28 -> 75147.49
A29: Dirt/Soil-Clean Fill | B29: =M20 -> Concrete & dirt | C29: {=_xlfn.XLOOKUP(B29,_xlfn.VSTACK($M$11:$M$13,$M$15:$M$21),_xlfn.VSTACK($R$11:$R$13,$R$15:$R$21))} -> 73 | D29: 59185.2 | E29: =C29*D29 -> 4320519.6 | G29: Dirt/Soil-Clean Fill | H29: =$M$15 -> Mixed C&D | I29: {=_xlfn.XLOOKUP(H29,_xlfn.VSTACK($M$11:$M$13,$M$15:$M$21),_xlfn.VSTACK($R$11:$R$13,$R$15:$R$21))} -> 100 | J29: 59185.2 | K29: =I29*J29 -> 5918520
A31: TOTAL COSTS | G31: TOTAL COSTS
A32: Total Variable Costs | B32: =SUM(E15:E29) -> 4911297.9 | G32: Total Variable Costs | H32: =SUM(K15:K29) -> 6741825.3
A33: Total Fixed Costs | B33: =C11 -> 657815 | G33: Total Fixed Costs | H33: =I11 -> 657815
A34: Total Costs | B34: =B32+B33 -> 5569112.9 | G34: Total Costs | H34: =H32+H33 -> 7399640.3
A36: Hauling Costs using wood bunkers (without TRUE) | G36: Hauling costs avoided with reusable steel bunkers (without TRUE)
A37: Wood bunkers | B37: =B39/B38 -> 20 | G37: Wood bunkers | H37: 0 | I37: * Steel bunkers were used on the project
A38: Tons of wood per bunker | B38: 5 | G38: Tons of wood per bunker | H38: 0
A39: Total wood saved (tons) | B39: 100 | G39: Total wood saved (tons) | H39: 0
A40: Hauling cost avoided | B40: =B37*'Entire Project Overiew'!$O$11 -> 10900 | C40: * $545 per haul per wood bunker | G40: Hauling cost avoided | H40: =H37*'Entire Project Overiew'!$O$11 -> 0 | I40: * Steel bunkers were sent back to be reused
A41: Disposal cost avoided | B41: =B39*'Entire Project Overiew'!$P$16 -> 8500 | C41: * $85 per ton of wood hauled | G41: Disposal cost avoided | H41: =H39*'Entire Project Overiew'!$P$16 -> 0
A42: Total hauling costs | B42: =B40+B41 -> 19400 | G42: Total hauling costs | H42: =H40+H41 -> 0

Sheet Monthly $ Break Down (TRUE)
A1: GATEWAY CONSTRUCTION TRUE COST BENEFIT ANALYSIS
B3: Gateway Hauling Metrics with TRUE (>90% Diversion) | AS3: Total Cost Savings with TRUE (for 12 months)
A4: Year: | B4: 2022 | C4: 2022 | D4: 2023 | E4: 2023 | F4: 2023 | G4: 2023 | H4: 2023 | I4: 2023 | J4: 2023 | K4: 2023 | L4: 2023 | M4: 2024 | N4: 2024 | O4: 2024 | P4: 2024 | Q4: 2024 | R4: 2024 | S4: 2024 | T4: 2024 | U4: 2024 | V4: 2024 | W4: 2024 | X4: 2024 | Y4: 2025 | Z4: 2025 | AA4: 2025 | AB4: 2025 | AC4: 2025 | AD4: 2025 | AE4: 2025 | AF4: 2025 | AG4: 2025 | AH4: 2025 | AI4: 2025 | AJ4: 2025 | AK4: 2026 | AL4: 2026 | AM4: 2026 | AN4: 2026 | AO4: 2026 | AP4: 2026 | AQ4: Total: | AS4: Total Costs with source seperation (pursuing TRUE) | AW4: =AQ64 -> 5569112.9
A5: Month: | B5: Nov | C5: Dec | D5: Apr | E5: May | F5: Jun | G5: Jul | H5: Aug | I5: Sep | J5: Oct | K5: Nov | L5: Dec | M5: Jan | N5: Feb | O5: Mar | P5: Apr | Q5: May | R5: Jun | S5: Jul | T5: Aug | U5: Sep | V5: Oct | W5: Nov | X5: Dec | Y5: Jan | Z5: Feb | AA5: Mar | AB5: Apr | AC5: May | AD5: Jun | AE5: Jul | AF5: Aug | AG5: Sept | AH5: Oct | AI5: Nov | AJ5: Dec | AK5: Jan | AL5: Feb | AM5: Mar | AN5: Apr | AO5: May | AP5: Jun | AS5: Total Costs without any source seperation (not pursuing TRUE) | AW5: ='Monthly $ Break Down (wo TRUE('!AQ32 -> 7399640.3
A6: Fixed Hauling Fees | AS6: Total Cost Savings from source seperating | AW6: =AW5-AW4 -> 1830527.3
A7: Total hauls | B7: =COUNTIF('Raw Data'!$M$11:$M$1217,DATE(2022,11,1)) -> 28 | C7: =COUNTIF('Raw Data'!$M$11:$M$1217,DATE(2022,12,1)) -> 3 | D7: =COUNTIF('Raw Data'!$M$11:$M$1217,DATE(2023,4,1)) -> 6 | E7: =COUNTIF('Raw Data'!$M$11:$M$1217,DATE(2023,5,1)) -> 75 | F7: =COUNTIF('Raw Data'!$M$11:$M$1217,DATE(2023,6,1)) -> 77 | G7: =COUNTIF('Raw Data'!$M$11:$M$1217,DATE(2023,7,1)) -> 4 | H7: =COUNTIF('Raw Data'!$M$11:$M$1217,DATE(2023,8,1)) -> 7 | I7: =COUNTIF('Raw Data'!$M$11:$M$1217,DATE(2023,9,1)) -> 7 | J7: =COUNTIF('Raw Data'!$M$11:$M$1217,DATE(2023,10,1)) -> 17 | K7: =COUNTIF('Raw Data'!$M$11:$M$1217,DATE(2023,11,1)) -> 10 | L7: =COUNTIF('Raw Data'!$M$11:$M$1217,DATE(2023,12,1)) -> 6 | M7: =COUNTIF('Raw Data'!$M$11:$M$1217,DATE(2024,1,1)) -> 21 | N7: =COUNTIF('Raw Data'!$M$11:$M$1217,DATE(2024,2,1)) -> 27 | O7: =COUNTIF('Raw Data'!$M$11:$M$1217,DATE(2024,3,1)) -> 37 | P7: =COUNTIF('Raw Data'!$M$11:$M$1217,DATE(2024,4,1)) -> 10 | Q7: =COUNTIF('Raw Data'!$M$11:$M$1217,DATE(2024,5,1)) -> 12 | R7: =COUNTIF('Raw Data'!$M$11:$M$1217,DATE(2024,6,1)) -> 10 | S7: =COUNTIF('Raw Data'!$M$11:$M$1217,DATE(2024,7,1)) -> 10 | T7: =COUNTIF('Raw Data'!$M$11:$M$1217,DATE(2024,8,1)) -> 26 | U7: =COUNTIF('Raw Data'!$M$11:$M$1217,DATE(2024,9,1)) -> 36 | V7: =COUNTIF('Raw Data'!$M$11:$M$1217,DATE(2024,10,1)) -> 81 | W7: =COUNTIF('Raw Data'!$M$11:$M$1217,DATE(2024,11,1)) -> 38 | X7: =COUNTIF('Raw Data'!$M$11:$M$1217,DATE(2024,12,1)) -> 36 | Y7: =COUNTIF('Raw Data'!$M$11:$M$1217,DATE(2025,1,1)) -> 29 | Z7: =COUNTIF('Raw Data'!$M$11:$M$1217,DATE(2025,2,1)) -> 36 | AA7: =COUNTIF('Raw Data'!$M$11:$M$1217,DATE(2025,3,1)) -> 49 | AB7: =COUNTIF('Raw Data'!$M$11:$M$1217,DATE(2025,4,1)) -> 48 | AC7: =COUNTIF('Raw Data'!$M$11:$M$1217,DATE(2025,5,1)) -> 57 | AD7: =COUNTIF('Raw Data'!$M$11:$M$1217,DATE(2025,6,1)) -> 52 | AE7: =COUNTIF('Raw Data'!$M$11:$M$1217,DATE(2025,7,1)) -> 39 | AF7: =COUNTIF('Raw Data'!$M$11:$M$1217,DATE(2025,8,1)) -> 33 | AG7: =COUNTIF('Raw Data'!$M$11:$M$1217,DATE(2025,9,1)) -> 37 | AH7: =COUNTIF('Raw Data'!$M$11:$M$1217,DATE(2025,10,1)) -> 46 | AI7: =COUNTIF('Raw Data'!$M$11:$M$1217,DATE(2025,11,1)) -> 29 | AJ7: =COUNTIF('Raw Data'!$M$11:$M$1217,DATE(2025,12,1)) -> 39 | AK7: =COUNTIF('Raw Data'!$M$11:$M$1217,DATE(2026,1,1)) -> 54 | AL7: =COUNTIF('Raw Data'!$M$11:$M$1217,DATE(2026,2,1)) -> 28 | AM7: =COUNTIF('Raw Data'!$M$11:$M$1217,DATE(2026,3,1)) -> 19 | AN7: =COUNTIF('Raw Data'!$M$11:$M$1217,DATE(2026,4,1)) -> 12 | AO7: =COUNTIF('Raw Data'!$M$11:$M$1217,DATE(2026,5,1)) -> 10 | AP7: =COUNTIF('Raw Data'!$M$11:$M$1217,DATE(2026,6,1)) -> 6 | AQ7: =SUM(B7:AP7) -> 1207
A8: Fixed Hauling Costs | B8: =B7*'Entire Project Overiew'!$O$11 -> 15260 | C8: =C7*'Entire Project Overiew'!$O$11 -> 1635 | D8: =D7*'Entire Project Overiew'!$O$11 -> 3270 | E8: =E7*'Entire Project Overiew'!$O$11 -> 40875 | F8: =F7*'Entire Project Overiew'!$O$11 -> 41965 | G8: =G7*'Entire Project Overiew'!$O$11 -> 2180 | H8: =H7*'Entire Project Overiew'!$O$11 -> 3815 | I8: =I7*'Entire Project Overiew'!$O$11 -> 3815 | ... AP8: =AP7*'Entire Project Overiew'!$O$11 -> 3270 | AQ8: =SUM(B8:AP8) -> 657815
A10: MSW Trash
A11: Trash Sorted for Recovery | B11: 0 | C11: 0 | D11: 4.6255 | E11: 2.9435 | F11: 0 | G11: 1.5312 | H11: 0 | I11: 0 | J11: 0 | K11: 0 | L11: 0 | M11: 0 | N11: 0 | O11: 0 | P11: 0 | Q11: 0 | R11: 0 | S11: 0 | T11: 0 | U11: 0 | V11: 0 | W11: 0 | X11: 0 | Y11: 0 | Z11: 0 | AA11: 0 | AB11: 0 | AC11: 0 | AD11: 0 | AE11: 0 | AF11: 0 | AG11: 0 | AH11: 0 | AI11: 0 | AJ11: 0 | AK11: 0 | AL11: 0 | AM11: 0 | AN11: 0 | AO11: 0 | AP11: 0 | AQ11: =SUM(B11:AP11) -> 9.1002
A12: Total MSW Trash | B12: =B11 -> 0 | C12: =C11 -> 0 | D12: =D11 -> 4.6255 | E12: =E11 -> 2.9435 | F12: =F11 -> 0 | G12: =G11 -> 1.5312 | H12: =H11 -> 0 | I12: =I11 -> 0 | ... AP12: =AP11 -> 0 | AQ12: =SUM(B12:AP12) -> 9.1002
A13: Total MSW Trash Costs | B13: =B12*'Entire Project Overiew'!$R$11 -> 0 | C13: =C12*'Entire Project Overiew'!$R$11 -> 0 | D13: =D12*'Entire Project Overiew'!$R$11 -> 462.55 | E13: =E12*'Entire Project Overiew'!$R$11 -> 294.35 | F13: =F12*'Entire Project Overiew'!$R$11 -> 0 | G13: =G12*'Entire Project Overiew'!$R$11 -> 153.12 | H13: =H12*'Entire Project Overiew'!$R$11 -> 0 | I13: =I12*'Entire Project Overiew'!$R$11 -> 0 | ... AP13: =AP12*'Entire Project Overiew'!$R$11 -> 0 | AQ13: =SUM(B13:AP13) -> 910.02
A15: Recycling
A16: Plastics & Plastic Packaging Materials | B16: 0 | C16: 0 | D16: 0 | E16: 0 | F16: 0 | G16: 0 | H16: 0 | I16: 0 | J16: 0 | K16: 0 | L16: 0 | M16: 0 | N16: 0 | O16: 0 | P16: 0 | Q16: 0 | R16: 0 | S16: 0 | T16: 0 | U16: 0 | V16: 0 | W16: 0.846 | X16: 0.7 | Y16: 0 | Z16: 0 | AA16: 0 | AB16: 0 | AC16: 0 | AD16: 0 | AE16: 0 | AF16: 0 | AG16: 2.07 | AH16: 0 | AI16: 0 | AJ16: 0 | AK16: 0 | AL16: 0 | AM16: 0 | AN16: 0 | AO16: 0 | AP16: 0 | AQ16: =SUM(B16:AP16) -> 3.616
A17: Total Recycling | B17: =B16 -> 0 | C17: =C16 -> 0 | D17: =D16 -> 0 | E17: =E16 -> 0 | F17: =F16 -> 0 | G17: =G16 -> 0 | H17: =H16 -> 0 | I17: =I16 -> 0 | ... AP17: =AP16 -> 0 | AQ17: =SUM(B17:AP17) -> 3.616
A18: Total Recycling Costs | B18: =B17*'Entire Project Overiew'!$R$12 -> 0 | C18: =C17*'Entire Project Overiew'!$R$12 -> 0 | D18: =D17*'Entire Project Overiew'!$R$12 -> 0 | E18: =E17*'Entire Project Overiew'!$R$12 -> 0 | F18: =F17*'Entire Project Overiew'!$R$12 -> 0 | G18: =G17*'Entire Project Overiew'!$R$12 -> 0 | H18: =H17*'Entire Project Overiew'!$R$12 -> 0 | I18: =I17*'Entire Project Overiew'!$R$12 -> 0 | ... AP18: =AP17*'Entire Project Overiew'!$R$12 -> 0 | AQ18: =SUM(B18:AP18) -> 361.6
A20: Compost
A21: Compost | B21: 0 | C21: 0 | D21: 0 | E21: 0 | F21: 0 | G21: 0 | H21: 0 | I21: 0 | J21: 0 | K21: 0 | L21: 0 | M21: 0 | N21: 0 | O21: 0 | P21: 0 | Q21: 0 | R21: 0 | S21: 0 | T21: 0 | U21: 0 | V21: 0 | W21: 0 | X21: 0 | Y21: 0 | Z21: 0 | AA21: 0 | AB21: 0 | AC21: 0 | AD21: 0 | AE21: 0 | AF21: 0 | AG21: 0.75 | AH21: 0 | AI21: 0 | AJ21: 0 | AK21: 0 | AL21: 0 | AM21: 0 | AN21: 0 | AO21: 0 | AP21: 0 | AQ21: =SUM(B21:AP21) -> 0.75
A22: Total Compost | B22: =B21 -> 0 | C22: =C21 -> 0 | D22: =D21 -> 0 | E22: =E21 -> 0 | F22: =F21 -> 0 | G22: =G21 -> 0 | H22: =H21 -> 0 | I22: =I21 -> 0 | ... AP22: =AP21 -> 0 | AQ22: =SUM(B22:AP22) -> 0.75
A23: Total Compost Costs | B23: =B22*'Entire Project Overiew'!$R$13 -> 0 | C23: =C22*'Entire Project Overiew'!$R$13 -> 0 | D23: =D22*'Entire Project Overiew'!$R$13 -> 0 | E23: =E22*'Entire Project Overiew'!$R$13 -> 0 | F23: =F22*'Entire Project Overiew'!$R$13 -> 0 | G23: =G22*'Entire Project Overiew'!$R$13 -> 0 | H23: =H22*'Entire Project Overiew'!$R$13 -> 0 | I23: =I22*'Entire Project Overiew'!$R$13 -> 0 | ... AP23: =AP22*'Entire Project Overiew'!$R$13 -> 0 | AQ23: =SUM(B23:AP23) -> 75
A25: Mixed C&D
A26: Miscellaneous Debris | B26: 0 | C26: 0 | D26: 11.3245 | E26: 7.2065 | F26: 0 | G26: 3.7488 | H26: 0 | I26: 0 | J26: 1.1244 | K26: 0 | L26: 0 | M26: 0.9384 | N26: 0 | O26: 0 | P26: 0 | Q26: 0 | R26: 0 | S26: 0 | T26: 0 | U26: 0 | V26: 0 | W26: 0 | X26: 0 | Y26: 0 | Z26: 0 | AA26: 0 | AB26: 0 | AC26: 0 | AD26: 0 | AE26: 0 | AF26: 0 | AG26: 0 | AH26: 0 | AI26: 0 | AJ26: 0 | AK26: 0 | AL26: 0 | AM26: 0 | AN26: 0 | AO26: 0 | AP26: 0 | AQ26: =SUM(B26:AP26) -> 24.3426
A27: Alternate Daily Cover (ADC) | B27: 0.41 | C27: 0.3348 | D27: 0 | E27: 0 | F27: 1.12 | G27: 0 | H27: 0 | I27: 0 | J27: 0 | K27: 5.32 | L27: 1.8 | M27: 3.24 | N27: 6.2 | O27: 6.985 | P27: 5.69 | Q27: 5.11 | R27: 4.04 | S27: 3.74 | T27: 8.6 | U27: 2.79 | V27: 0.54 | W27: 1.1355 | X27: 3.72 | Y27: 6.64 | Z27: 2.93 | AA27: 4.21 | AB27: 10.35 | AC27: 15.13 | AD27: 36.95 | AE27: 24.43 | AF27: 17.66 | AG27: 12.33 | AH27: 28.007 | AI27: 5.93 | AJ27: 18.3404 | AK27: 35.3696 | AL27: 26.6619 | AM27: 13.2152 | AN27: 13.0173 | AO27: 18.6604 | AP27: 3.8268 | AQ27: =SUM(B27:AP27) -> 354.4339
A28: Mixed Recyclables | B28: 0.33 | C28: 0.28 | D28: 0 | E28: 0 | F28: 0.91 | G28: 0 | H28: 0 | I28: 0 | J28: 2.8056 | K28: 4.31 | L28: 1.46 | M28: 5.5676 | N28: 5.01 | O28: 6.504 | P28: 4.6 | Q28: 4.49 | R28: 3.26 | S28: 3.03 | T28: 6.99 | U28: 10.29 | V28: 0.44 | W28: 0.9 | X28: 3 | Y28: 5.39 | Z28: 2.38 | AA28: 3.39 | AB28: 8.39 | AC28: 12.24 | AD28: 29.94 | AE28: 19.84 | AF28: 14.32 | AG28: 10.18 | AH28: 22.73 | AI28: 4.81 | AJ28: 14.8662 | AK28: 28.6564 | AL28: 21.6019 | AM28: 10.7069 | AN28: 10.5465 | AO28: 15.0558 | AP28: 3.1006 | AQ28: =SUM(B28:AP28) -> 302.3215
A29: Waste (Trash) | B29: 0.34 | C29: 0.27 | D29: 0 | E29: 0 | F29: 0.93 | G29: 0 | H29: 0 | I29: 0 | J29: 0 | K29: 4.36 | L29: 1.48 | M29: 2.64 | N29: 5.08 | O29: 5.73 | P29: 4.64 | Q29: 4.16 | R29: 3.28 | S29: 3.07 | T29: 7.05 | U29: 2.3 | V29: 0.45 | W29: 0.91 | X29: 3.02 | Y29: 5.45 | Z29: 2.4 | AA29: 3.41 | AB29: 8.48 | AC29: 12.3836 | AD29: 30.26 | AE29: 20.05 | AF29: 14.46 | AG29: 8.45 | AH29: 22.9 | AI29: 4.86 | AJ29: 15.0126 | AK29: 28.9539 | AL29: 21.826 | AM29: 10.8181 | AN29: 10.6561 | AO29: 15.1337 | AP29: 3.1326 | AQ29: =SUM(B29:AP29) -> 288.3466
A30: Total Mixed C&D | B30: =SUM(B26:B29) -> 1.08 | C30: =SUM(C26:C29) -> 0.8848 | D30: =SUM(D26:D29) -> 11.3245 | E30: =SUM(E26:E29) -> 7.2065 | F30: =SUM(F26:F29) -> 2.96 | G30: =SUM(G26:G29) -> 3.7488 | H30: =SUM(H26:H29) -> 0 | I30: =SUM(I26:I29) -> 0 | ... AP30: =SUM(AP26:AP29) -> 10.06 | AQ30: =SUM(B30:AP30) -> 969.4446
A31: Total Mixed C&D Costs | B31: =B30*'Entire Project Overiew'!$R$15 -> 108 | C31: =C30*'Entire Project Overiew'!$R$15 -> 88.48 | D31: =D30*'Entire Project Overiew'!$R$15 -> 1132.45 | E31: =E30*'Entire Project Overiew'!$R$15 -> 720.65 | F31: =F30*'Entire Project Overiew'!$R$15 -> 296 | G31: =G30*'Entire Project Overiew'!$R$15 -> 374.88 | H31: =H30*'Entire Project Overiew'!$R$15 -> 0 | I31: =I30*'Entire Project Overiew'!$R$15 -> 0 | ... AP31: =AP30*'Entire Project Overiew'!$R$15 -> 1006 | AQ31: =SUM(B31:AP31) -> 96944.46
A33: Wood
A34: Wood - Clean | B34: 0 | C34: 1.31 | D34: 0 | E34: 0 | F34: 0 | G34: 7.92 | H34: 19.4 | I34: 16.14 | J34: 32.5 | K34: 5.02 | L34: 3.88 | M34: 34.804 | N34: 6.13 | O34: 41.19 | P34: 22.55 | Q34: 14.34 | R34: 13.22 | S34: 11.64 | T34: 25.83 | U34: 41.02 | V34: 59.43 | W34: 11.0545 | X34: 15.92 | Y34: 8.91 | Z34: 14.35 | AA34: 19.44 | AB34: 17.39 | AC34: 33.0164 | AD34: 21.14 | AE34: 12.47 | AF34: 0.9 | AG34: 5.82 | AH34: 26.26 | AI34: 78.94 | AJ34: 64.74 | AK34: 29.13 | AL34: 16.46 | AM34: 6.45 | AN34: 8.33 | AO34: 0 | AP34: 4.43 | AQ34: =SUM(B34:AP34) -> 751.4749
A35: Total Wood | B35: =B34 -> 0 | C35: =C34 -> 1.31 | D35: =D34 -> 0 | E35: =E34 -> 0 | F35: =F34 -> 0 | G35: =G34 -> 7.92 | H35: =H34 -> 19.4 | I35: =I34 -> 16.14 | ... AP35: =AP34 -> 4.43 | AQ35: =SUM(B35:AP35) -> 751.4749
A36: Total Wood Costs | B36: =B35*'Entire Project Overiew'!$R$16 -> 0 | C36: =C35*'Entire Project Overiew'!$R$16 -> 111.35 | D36: =D35*'Entire Project Overiew'!$R$16 -> 0 | E36: =E35*'Entire Project Overiew'!$R$16 -> 0 | F36: =F35*'Entire Project Overiew'!$R$16 -> 0 | G36: =G35*'Entire Project Overiew'!$R$16 -> 673.2 | H36: =H35*'Entire Project Overiew'!$R$16 -> 1649 | I36: =I35*'Entire Project Overiew'!$R$16 -> 1371.9 | ... AP36: =AP35*'Entire Project Overiew'!$R$16 -> 376.55 | AQ36: =SUM(B36:AP36) -> 63875.367
A38: Drywall
A39: Drywall - Demo & painted | B39: 0 | C39: 0 | D39: 0 | E39: 0 | F39: 0 | G39: 0 | H39: 0 | I39: 0 | J39: 0 | K39: 0 | L39: 0 | M39: 0 | N39: 0 | O39: 0 | P39: 0 | Q39: 0 | R39: 0 | S39: 0 | T39: 5.83 | U39: 0 | V39: 0 | W39: 0 | X39: 0 | Y39: 0 | Z39: 0 | AA39: 0 | AB39: 0 | AC39: 0 | AD39: 0 | AE39: 0 | AF39: 0 | AG39: 9.67 | AH39: 4.95 | AI39: 0 | AJ39: 0 | AK39: 0 | AL39: 0 | AM39: 0 | AN39: 0 | AO39: 0 | AP39: 0 | AQ39: =SUM(B39:AP39) -> 20.45
A40: Drywall - Clean/Unpainted | B40: 0 | C40: 0 | D40: 0 | E40: 0 | F40: 0 | G40: 0 | H40: 0 | I40: 0 | J40: 0 | K40: 0 | L40: 0 | M40: 0 | N40: 0 | O40: 0 | P40: 0 | Q40: 0 | R40: 0 | S40: 0 | T40: 0 | U40: 14.37 | V40: 37.1 | W40: 70.66 | X40: 81.7 | Y40: 68.46 | Z40: 93.07 | AA40: 112.39 | AB40: 90.8 | AC40: 80.24 | AD40: 10.63 | AE40: 42.72 | AF40: 60.02 | AG40: 67.84 | AH40: 32.32 | AI40: 31.5 | AJ40: 34.95 | AK40: 10.8 | AL40: 0 | AM40: 0 | AN40: 0 | AO40: 0 | AP40: 0 | AQ40: =SUM(B40:AP40) -> 939.57
A41: Total Drywall | B41: =SUM(B39:B40) -> 0 | C41: =SUM(C39:C40) -> 0 | D41: =SUM(D39:D40) -> 0 | E41: =SUM(E39:E40) -> 0 | F41: =SUM(F39:F40) -> 0 | G41: =SUM(G39:G40) -> 0 | H41: =SUM(H39:H40) -> 0 | I41: =SUM(I39:I40) -> 0 | ... AP41: =SUM(AP39:AP40) -> 0 | AQ41: =SUM(B41:AP41) -> 960.02
A42: Total Drywall Costs | B42: =B41*'Entire Project Overiew'!$R$17 -> 0 | C42: =C41*'Entire Project Overiew'!$R$17 -> 0 | D42: =D41*'Entire Project Overiew'!$R$17 -> 0 | E42: =E41*'Entire Project Overiew'!$R$17 -> 0 | F42: =F41*'Entire Project Overiew'!$R$17 -> 0 | G42: =G41*'Entire Project Overiew'!$R$17 -> 0 | H42: =H41*'Entire Project Overiew'!$R$17 -> 0 | I42: =I41*'Entire Project Overiew'!$R$17 -> 0 | ... AP42: =AP41*'Entire Project Overiew'!$R$17 -> 0 | AQ42: =SUM(B42:AP42) -> 52801.1
A44: Concrete & dirt
A45: Asphalt - Pavement & Grinding | B45: 0 | C45: 0 | D45: 0 | E45: 0 | F45: 0 | G45: 0 | H45: 0 | I45: 0 | J45: 0 | K45: 0 | L45: 0 | M45: 0 | N45: 0 | O45: 0 | P45: 0 | Q45: 0 | R45: 0 | S45: 0 | T45: 0 | U45: 0 | V45: 0 | W45: 0 | X45: 0 | Y45: 0 | Z45: 0 | AA45: 0 | AB45: 0 | AC45: 0 | AD45: 29.41 | AE45: 0 | AF45: 0 | AG45: 0 | AH45: 21.42 | AI45: 2.5 | AJ45: 46.1709 | AK45: 271.0706 | AL45: 9.85 | AM45: 0 | AN45: 0 | AO45: 0 | AP45: 0 | AQ45: =SUM(B45:AP45) -> 380.4215
A46: Concrete | B46: 511.15 | C46: 0 | D46: 71.94 | E46: 1499.39 | F46: 1535.31 | G46: 7.11 | H46: 17.37 | I46: 17.8 | J46: 31.34 | K46: 16.32 | L46: 12.24 | M46: 47.71 | N46: 53.9 | O46: 87.12 | P46: 0 | Q46: 4.95 | R46: 14.31 | S46: 27.24 | T46: 50.15 | U46: 74.54 | V46: 281.26 | W46: 36.64 | X46: 13.66 | Y46: 6.75 | Z46: 11.13 | AA46: 0 | AB46: 7.59 | AC46: 30.1 | AD46: 15.57 | AE46: 12.32 | AF46: 47.66 | AG46: 85.75 | AH46: 67.49 | AI46: 3.2 | AJ46: 64.1707 | AK46: 112.749 | AL46: 8 | AM46: 19.92 | AN46: 0 | AO46: 0 | AP46: 0 | AQ46: =SUM(B46:AP46) -> 4903.8497
A47: Dirt/Soil-Clean Fill | B47: 0 | C47: 0 | D47: 0 | E47: 0 | F47: 0 | G47: 0 | H47: 0 | I47: 0 | J47: 59185.2 | K47: 0 | L47: 0 | M47: 0 | N47: 0 | O47: 0 | P47: 0 | Q47: 0 | R47: 0 | S47: 0 | T47: 0 | U47: 0 | V47: 0 | W47: 0 | X47: 0 | Y47: 0 | Z47: 0 | AA47: 0 | AB47: 0 | AC47: 0 | AD47: 0 | AE47: 0 | AF47: 0 | AG47: 0 | AH47: 0 | AI47: 0 | AJ47: 0 | AK47: 0 | AL47: 0 | AM47: 0 | AN47: 0 | AO47: 0 | AP47: 0 | AQ47: =SUM(B47:AP47) -> 59185.2
A48: Total Concrete & Dirt | B48: =SUM(B45:B47) -> 511.15 | C48: =SUM(C45:C47) -> 0 | D48: =SUM(D45:D47) -> 71.94 | E48: =SUM(E45:E47) -> 1499.39 | F48: =SUM(F45:F47) -> 1535.31 | G48: =SUM(G45:G47) -> 7.11 | H48: =SUM(H45:H47) -> 17.37 | I48: =SUM(I45:I47) -> 17.8 | ... AP48: =SUM(AP45:AP47) -> 0 | AQ48: =SUM(B48:AP48) -> 64469.471
...

Sheet Monthly $ Break Down (wo TRUE(
A1: GATEWAY CONSTRUCTION TRUE COST BENEFIT ANALYSIS
B3: Typical Hauling Metrics without TRUE (no source seperation) | AS3: Total Cost Savings with TRUE (for 12 months)
A4: Year: | B4: 2022 | C4: 2022 | D4: 2023 | E4: 2023 | F4: 2023 | G4: 2023 | H4: 2023 | I4: 2023 | J4: 2023 | K4: 2023 | L4: 2023 | M4: 2024 | N4: 2024 | O4: 2024 | P4: 2024 | Q4: 2024 | R4: 2024 | S4: 2024 | T4: 2024 | U4: 2024 | V4: 2024 | W4: 2024 | X4: 2024 | Y4: 2025 | Z4: 2025 | AA4: 2025 | AB4: 2025 | AC4: 2025 | AD4: 2025 | AE4: 2025 | AF4: 2025 | AG4: 2025 | AH4: 2025 | AI4: 2025 | AJ4: 2025 | AK4: 2026 | AL4: 2026 | AM4: 2026 | AN4: 2026 | AO4: 2026 | AP4: 2026 | AQ4: Total: | AS4: Total Costs with source seperation (pursuing TRUE) | AW4: ='Monthly $ Break Down (TRUE)'!AQ64 -> 5569112.9
A5: Month: | B5: Nov | C5: Dec | D5: Apr | E5: May | F5: Jun | G5: Jul | H5: Aug | I5: Sep | J5: Oct | K5: Nov | L5: Dec | M5: Jan | N5: Feb | O5: Mar | P5: Apr | Q5: May | R5: Jun | S5: Jul | T5: Aug | U5: Sep | V5: Oct | W5: Nov | X5: Dec | Y5: Jan | Z5: Feb | AA5: Mar | AB5: Apr | AC5: May | AD5: Jun | AE5: Jul | AF5: Aug | AG5: Sept | AH5: Oct | AI5: Nov | AJ5: Dec | AK5: Jan | AL5: Feb | AM5: Mar | AN5: Apr | AO5: May | AP5: Jun | AS5: Total Costs without any source seperation (not pursuing TRUE) | AW5: =AQ32 -> 7399640.3
A6: Fixed Hauling Fees | AS6: Total Cost Savings from source seperating | AW6: =AW5-AW4 -> 1830527.3
A7: Total hauls | B7: =COUNTIF('Raw Data'!$M$11:$M$1217,DATE(2022,11,1)) -> 28 | C7: =COUNTIF('Raw Data'!$M$11:$M$1217,DATE(2022,12,1)) -> 3 | D7: =COUNTIF('Raw Data'!$M$11:$M$1217,DATE(2023,4,1)) -> 6 | E7: =COUNTIF('Raw Data'!$M$11:$M$1217,DATE(2023,5,1)) -> 75 | F7: =COUNTIF('Raw Data'!$M$11:$M$1217,DATE(2023,6,1)) -> 77 | G7: =COUNTIF('Raw Data'!$M$11:$M$1217,DATE(2023,7,1)) -> 4 | H7: =COUNTIF('Raw Data'!$M$11:$M$1217,DATE(2023,8,1)) -> 7 | I7: =COUNTIF('Raw Data'!$M$11:$M$1217,DATE(2023,9,1)) -> 7 | J7: =COUNTIF('Raw Data'!$M$11:$M$1217,DATE(2023,10,1)) -> 17 | K7: =COUNTIF('Raw Data'!$M$11:$M$1217,DATE(2023,11,1)) -> 10 | L7: =COUNTIF('Raw Data'!$M$11:$M$1217,DATE(2023,12,1)) -> 6 | M7: =COUNTIF('Raw Data'!$M$11:$M$1217,DATE(2024,1,1)) -> 21 | N7: =COUNTIF('Raw Data'!$M$11:$M$1217,DATE(2024,2,1)) -> 27 | O7: =COUNTIF('Raw Data'!$M$11:$M$1217,DATE(2024,3,1)) -> 37 | P7: =COUNTIF('Raw Data'!$M$11:$M$1217,DATE(2024,4,1)) -> 10 | Q7: =COUNTIF('Raw Data'!$M$11:$M$1217,DATE(2024,5,1)) -> 12 | R7: =COUNTIF('Raw Data'!$M$11:$M$1217,DATE(2024,6,1)) -> 10 | S7: =COUNTIF('Raw Data'!$M$11:$M$1217,DATE(2024,7,1)) -> 10 | T7: =COUNTIF('Raw Data'!$M$11:$M$1217,DATE(2024,8,1)) -> 26 | U7: =COUNTIF('Raw Data'!$M$11:$M$1217,DATE(2024,9,1)) -> 36 | V7: =COUNTIF('Raw Data'!$M$11:$M$1217,DATE(2024,10,1)) -> 81 | W7: =COUNTIF('Raw Data'!$M$11:$M$1217,DATE(2024,11,1)) -> 38 | X7: =COUNTIF('Raw Data'!$M$11:$M$1217,DATE(2024,12,1)) -> 36 | Y7: =COUNTIF('Raw Data'!$M$11:$M$1217,DATE(2025,1,1)) -> 29 | Z7: =COUNTIF('Raw Data'!$M$11:$M$1217,DATE(2025,2,1)) -> 36 | AA7: =COUNTIF('Raw Data'!$M$11:$M$1217,DATE(2025,3,1)) -> 49 | AB7: =COUNTIF('Raw Data'!$M$11:$M$1217,DATE(2025,4,1)) -> 48 | AC7: =COUNTIF('Raw Data'!$M$11:$M$1217,DATE(2025,5,1)) -> 57 | AD7: =COUNTIF('Raw Data'!$M$11:$M$1217,DATE(2025,6,1)) -> 52 | AE7: =COUNTIF('Raw Data'!$M$11:$M$1217,DATE(2025,7,1)) -> 39 | AF7: =COUNTIF('Raw Data'!$M$11:$M$1217,DATE(2025,8,1)) -> 33 | AG7: =COUNTIF('Raw Data'!$M$11:$M$1217,DATE(2025,9,1)) -> 37 | AH7: =COUNTIF('Raw Data'!$M$11:$M$1217,DATE(2025,10,1)) -> 46 | AI7: =COUNTIF('Raw Data'!$M$11:$M$1217,DATE(2025,11,1)) -> 29 | AJ7: =COUNTIF('Raw Data'!$M$11:$M$1217,DATE(2025,12,1)) -> 39 | AK7: =COUNTIF('Raw Data'!$M$11:$M$1217,DATE(2026,1,1)) -> 54 | AL7: =COUNTIF('Raw Data'!$M$11:$M$1217,DATE(2026,2,1)) -> 28 | AM7: =COUNTIF('Raw Data'!$M$11:$M$1217,DATE(2026,3,1)) -> 19 | AN7: =COUNTIF('Raw Data'!$M$11:$M$1217,DATE(2026,4,1)) -> 12 | AO7: =COUNTIF('Raw Data'!$M$11:$M$1217,DATE(2026,5,1)) -> 10 | AP7: =COUNTIF('Raw Data'!$M$11:$M$1217,DATE(2026,6,1)) -> 6 | AQ7: =SUM(B7:AP7) -> 1207
A8: Fixed Hauling Costs | B8: =B7*'Entire Project Overiew'!$O$11 -> 15260 | C8: =C7*'Entire Project Overiew'!$O$11 -> 1635 | D8: =D7*'Entire Project Overiew'!$O$11 -> 3270 | E8: =E7*'Entire Project Overiew'!$O$11 -> 40875 | F8: =F7*'Entire Project Overiew'!$O$11 -> 41965 | G8: =G7*'Entire Project Overiew'!$O$11 -> 2180 | H8: =H7*'Entire Project Overiew'!$O$11 -> 3815 | I8: =I7*'Entire Project Overiew'!$O$11 -> 3815 | ... AP8: =AP7*'Entire Project Overiew'!$O$11 -> 3270 | AQ8: =SUM(B8:AP8) -> 657815
A10: Mixed C&D
A11: Trash Sorted for Recovery | B11: 0 | C11: 0 | D11: 4.6255 | E11: 2.9435 | F11: 0 | G11: 1.5312 | H11: 0 | I11: 0 | J11: 0 | K11: 0 | L11: 0 | M11: 0 | N11: 0 | O11: 0 | P11: 0 | Q11: 0 | R11: 0 | S11: 0 | T11: 0 | U11: 0 | V11: 0 | W11: 0 | X11: 0 | Y11: 0 | Z11: 0 | AA11: 0 | AB11: 0 | AC11: 0 | AD11: 0 | AE11: 0 | AF11: 0 | AG11: 0 | AH11: 0 | AI11: 0 | AJ11: 0 | AK11: 0 | AL11: 0 | AM11: 0 | AN11: 0 | AO11: 0 | AP11: 0 | AQ11: =SUM(B11:AP11) -> 9.1002
A12: Plastics & Plastic Packaging Materials | B12: 0 | C12: 0 | D12: 0 | E12: 0 | F12: 0 | G12: 0 | H12: 0 | I12: 0 | J12: 0 | K12: 0 | L12: 0 | M12: 0 | N12: 0 | O12: 0 | P12: 0 | Q12: 0 | R12: 0 | S12: 0 | T12: 0 | U12: 0 | V12: 0 | W12: 0.846 | X12: 0.7 | Y12: 0 | Z12: 0 | AA12: 0 | AB12: 0 | AC12: 0 | AD12: 0 | AE12: 0 | AF12: 0 | AG12: 2.07 | AH12: 0 | AI12: 0 | AJ12: 0 | AK12: 0 | AL12: 0 | AM12: 0 | AN12: 0 | AO12: 0 | AP12: 0 | AQ12: =SUM(B12:AP12) -> 3.616
A13: Compost | B13: 0 | C13: 0 | D13: 0 | E13: 0 | F13: 0 | G13: 0 | H13: 0 | I13: 0 | J13: 0 | K13: 0 | L13: 0 | M13: 0 | N13: 0 | O13: 0 | P13: 0 | Q13: 0 | R13: 0 | S13: 0 | T13: 0 | U13: 0 | V13: 0 | W13: 0 | X13: 0 | Y13: 0 | Z13: 0 | AA13: 0 | AB13: 0 | AC13: 0 | AD13: 0 | AE13: 0 | AF13: 0 | AG13: 0.75 | AH13: 0 | AI13: 0 | AJ13: 0 | AK13: 0 | AL13: 0 | AM13: 0 | AN13: 0 | AO13: 0 | AP13: 0 | AQ13: =SUM(B13:AP13) -> 0.75
A14: Miscellaneous Debris | B14: 0 | C14: 0 | D14: 11.3245 | E14: 7.2065 | F14: 0 | G14: 3.7488 | H14: 0 | I14: 0 | J14: 1.1244 | K14: 0 | L14: 0 | M14: 0.9384 | N14: 0 | O14: 0 | P14: 0 | Q14: 0 | R14: 0 | S14: 0 | T14: 0 | U14: 0 | V14: 0 | W14: 0 | X14: 0 | Y14: 0 | Z14: 0 | AA14: 0 | AB14: 0 | AC14: 0 | AD14: 0 | AE14: 0 | AF14: 0 | AG14: 0 | AH14: 0 | AI14: 0 | AJ14: 0 | AK14: 0 | AL14: 0 | AM14: 0 | AN14: 0 | AO14: 0 | AP14: 0 | AQ14: =SUM(B14:AP14) -> 24.3426
